Workbook

Sheet CANTEEN START-UP FUNDS
B1: CANTEEN MANAGEMENT DATA
A2: MEMBERS | C2: GROUP | D2: CONTRIBUTION
A3: 1 | B3: ELUSFA, PHEBE | C3: 1
A4: 2 | B4: FELECIO, RIZZA
A5: 3 | B5: FERNANDO, JAY-ANN
A6: 4 | B6: JOYAG, IVY
A7: 5 | B7: MAMALIMPING, ALJIREN
A8: 6 | B8: AGADIA, ROSANNA | C8: 2
A9: 7 | B9: ARBADO, LIGAYA
A10: 8 | B10: FERNANDO, MERIAM
A11: 9 | B11: LAMERA, FRITZI JULS
A12: 10 | B12: RAMA, GLORIETTA
A13: 11 | B13: TOLONES, JOHN MARK
A14: 12 | B14: BENDOL, EDAMAE | C14: 3 | D14: 1000
A15: 13 | B15: BUSAYONG, HANNAH JOY | D15: 660
A16: 14 | B16: DELOS SANTOS, GLORIA
A17: 15 | B17: LAO, JISAME
A18: 16 | B18: ROSETE, EMMIE | D18: 500
A19: 17 | B19: VILOAN, ANNALOU | C19: 4 | D19: 1000
A20: 18 | B20: ACUESA, IVY JOY
A21: 19 | B21: PAULINO, DELBERTH
A22: 20 | B22: GOMEZ, DESRIE JANE
A23: 21 | B23: MONDEJAR, DARYLL
A24: 22 | B24: BAYAMBAN, WILNER
A25: 23 | B25: PORRAS, CHARLYN | C25: A
A26: 24 | B26: BAUTISTA,JOSE
A27: 25 | B27: FRANCISCO, MERLYN
A28: 26 | B28: ARBADO, LOVELY
A29: 27 | B29: BUSAYONG, LYN | D29: 1000
D30: =sum(D3:D29) -> 4160

Sheet WEEKLY SCHEDULE
A2: CANTEEN DUTY CALENDAR — MON–FRI ROTATION (SEP 2026 – APR 2027)
A4: Group Color Legend & Personnel Assignments:
A5: Group 1 (Phebe, Rizza, Jay-Ann, Ivy, Aljiren) | H5: Group 2 (Rosanna, Ligaya, Meriam, Fritzi, Glorietta, John Mark) | O5: Group 3 (Edamae, Hannah Joy, Gloria, Jisame, Emmie) | V5: Group 4 (Annalou, Ivy Joy, Delberth, Desrie, Daryll, Wilner)
A7: 46266 | I7: 46296 | Q7: 46327 | Y7: 46357
A8: Mon | B8: Tue | C8: Wed | D8: Thu | E8: Fri | F8: Sat | G8: Sun | I8: Mon | J8: Tue | K8: Wed | L8: Thu | M8: Fri | N8: Sat | O8: Sun | Q8: Mon | R8: Tue | S8: Wed | T8: Thu | U8: Fri | V8: Sat | W8: Sun | Y8: Mon | Z8: Tue | AA8: Wed | AB8: Thu | AC8: Fri | AD8: Sat | AE8: Sun
B9: 1 - | C9: 2 - | D9: 3 - | E9: 4 - | F9: 5 (Off) | G9: 6 (Off) | L9: 1 (G3) | M9: 2 (G3) | N9: 3 (Off) | O9: 4 (Off) | W9: 1 (Off) | Z9: 1 (G4) | AA9: 2 (G4) | AB9: 3 (G4) | AC9: 4 (G4) | AD9: 5 (Off) | AE9: 6 (Off)
A10: 7 - | B10: 8 - | C10: 9 - | D10: 10 - | E10: 11 - | F10: 12 (Off) | G10: 13 (Off) | I10: 5 (G4) | J10: 6 (G4) | K10: 7 (G4) | L10: 8 (G4) | M10: 9 (G4) | N10: 10 (Off) | O10: 11 (Off) | Q10: 2 (G4) | R10: 3 (G4) | S10: 4 (G4) | T10: 5 (G4) | U10: 6 (G4) | V10: 7 (Off) | W10: 8 (Off) | Y10: 7 (G1) | Z10: 8 (G1) | AA10: 9 (G1) | AB10: 10 (G1) | AC10: 11 (G1) | AD10: 12 (Off) | AE10: 13 (Off)
A11: 14 - | B11: 15 - | C11: 16 (G1) | D11: 17 (G1) | E11: 18 (G1) | F11: 19 (Off) | G11: 20 (Off) | I11: 12 (G1) | J11: 13 (G1) | K11: 14 (G1) | L11: 15 (G1) | M11: 16 (G1) | N11: 17 (Off) | O11: 18 (Off) | Q11: 9 (G1) | R11: 10 (G1) | S11: 11 (G1) | T11: 12 (G1) | U11: 13 (G1) | V11: 14 (Off) | W11: 15 (Off) | Y11: 14 (G2) | Z11: 15 (G2) | AA11: 16 (G2) | AB11: 17 (G2) | AC11: 18 (G2) | AD11: 19 (Off) | AE11: 20 (Off)
A12: 21 (G2) | B12: 22 (G2) | C12: 23 (G2) | D12: 24 (G2) | E12: 25 (G2) | F12: 26 (Off) | G12: 27 (Off) | I12: 19 (G2) | J12: 20 (G2) | K12: 21 (G2) | L12: 22 (G2) | M12: 23 (G2) | N12: 24 (Off) | O12: 25 (Off) | Q12: 16 (G2) | R12: 17 (G2) | S12: 18 (G2) | T12: 19 (G2) | U12: 20 (G2) | V12: 21 (Off) | W12: 22 (Off) | Y12: 21 (G3) | Z12: 22 (G3) | AA12: 23 (G3) | AB12: 24 (G3) | AC12: 25 (G3) | AD12: 26 (Off) | AE12: 27 (Off)
A13: 28 (G3) | B13: 29 (G3) | C13: 30 (G3) | I13: 26 (G3) | J13: 27 (G3) | K13: 28 (G3) | L13: 29 (G3) | M13: 30 (G3) | N13: 31 (Off) | Q13: 23 (G3) | R13: 24 (G3) | S13: 25 (G3) | T13: 26 (G3) | U13: 27 (G3) | V13: 28 (Off) | W13: 29 (Off) | Y13: 28 (G4) | Z13: 29 (G4) | AA13: 30 (G4) | AB13: 31 (G4)
Q14: 30 (G4)
A18: 46388 | I18: 46419 | Q18: 46447 | Y18: 46478
A19: Mon | B19: Tue | C19: Wed | D19: Thu | E19: Fri | F19: Sat | G19: Sun | I19: Mon | J19: Tue | K19: Wed | L19: Thu | M19: Fri | N19: Sat | O19: Sun | Q19: Mon | R19: Tue | S19: Wed | T19: Thu | U19: Fri | V19: Sat | W19: Sun | Y19: Mon | Z19: Tue | AA19: Wed | AB19: Thu | AC19: Fri | AD19: Sat | AE19: Sun
E20: 1 (G4) | F20: 2 (Off) | G20: 3 (Off) | I20: 1 (G1) | J20: 2 (G1) | K20: 3 (G1) | L20: 4 (G1) | M20: 5 (G1) | N20: 6 (Off) | O20: 7 (Off) | Q20: 1 (G1) | R20: 2 (G1) | S20: 3 (G1) | T20: 4 (G1) | U20: 5 (G1) | V20: 6 (Off) | W20: 7 (Off) | AB20: 1 (G1) | AC20: 2 (G1) | AD20: 3 (Off) | AE20: 4 (Off)
A21: 4 (G1) | B21: 5 (G1) | C21: 6 (G1) | D21: 7 (G1) | E21: 8 (G1) | F21: 9 (Off) | G21: 10 (Off) | I21: 8 (G2) | J21: 9 (G2) | K21: 10 (G2) | L21: 11 (G2) | M21: 12 (G2) | N21: 13 (Off) | O21: 14 (Off) | Q21: 8 (G2) | R21: 9 (G2) | S21: 10 (G2) | T21: 11 (G2) | U21: 12 (G2) | V21: 13 (Off) | W21: 14 (Off) | Y21: 5 (G2) | Z21: 6 (G2) | AA21: 7 (G2) | AB21: 8 (G2) | AC21: 9 (G2) | AD21: 10 (Off) | AE21: 11 (Off)
A22: 11 (G2) | B22: 12 (G2) | C22: 13 (G2) | D22: 14 (G2) | E22: 15 (G2) | F22: 16 (Off) | G22: 17 (Off) | I22: 15 (G3) | J22: 16 (G3) | K22: 17 (G3) | L22: 18 (G3) | M22: 19 (G3) | N22: 20 (Off) | O22: 21 (Off) | Q22: 15 (G3) | R22: 16 (G3) | S22: 17 (G3) | T22: 18 (G3) | U22: 19 (G3) | V22: 20 (Off) | W22: 21 (Off) | Y22: 12 (G3) | Z22: 13 (G3) | AA22: 14 (G3) | AB22: 15 (G3) | AC22: 16 (G3) | AD22: 17 (Off) | AE22: 18 (Off)
A23: 18 (G3) | B23: 19 (G3) | C23: 20 (G3) | D23: 21 (G3) | E23: 22 (G3) | F23: 23 (Off) | G23: 24 (Off) | I23: 22 (G4) | J23: 23 (G4) | K23: 24 (G4) | L23: 25 (G4) | M23: 26 (G4) | N23: 27 (Off) | O23: 28 (Off) | Q23: 22 (G4) | R23: 23 (G4) | S23: 24 (G4) | T23: 25 (G4) | U23: 26 (G4) | V23: 27 (Off) | W23: 28 (Off) | Y23: 19 (G4) | Z23: 20 (G4) | AA23: 21 (G4) | AB23: 22 (G4) | AC23: 23 (G4) | AD23: 24 (Off) | AE23: 25 (Off)
A24: 25 (G4) | B24: 26 (G4) | C24: 27 (G4) | D24: 28 (G4) | E24: 29 (G4) | F24: 30 (Off) | G24: 31 (Off) | Q24: 29 (G1) | R24: 30 (G1) | S24: 31 (G1) | Y24: 26 (G1) | Z24: 27 (G1) | AA24: 28 (G1) | AB24: 29 (G1) | AC24: 30 (G1)

Sheet DAILY SALES RECORD
C1: DAILY SALES REPORT
I2: BEGINNING BALANCE:
D3: EXPENSES
A4: MONTH | C4: GROSS SALES | D4: SALARY | E4: WATER-SUBSIDY | F4: PURCHASED | G4: OTHERS | H4: TOTAL EXPENSES | I4: NET SALES
A5: SEPTEMBER | B5: 16 | H5: =SUM(D5:G5) -> 0 | I5: =C5-H5 -> 0
B6: 17 | H6: =SUM(D6:G6) -> 0 | I6: =C6-H6 -> 0
B7: 18 | H7: =SUM(D7:G7) -> 0 | I7: =C7-H7 -> 0
B8: 19 | H8: =SUM(D8:G8) -> 0 | I8: =C8-H8 -> 0
B9: 20 | H9: =SUM(D9:G9) -> 0 | I9: =C9-H9 -> 0
B10: 21 | H10: =SUM(D10:G10) -> 0 | I10: =C10-H10 -> 0
B11: 22 | H11: =SUM(D11:G11) -> 0 | I11: =C11-H11 -> 0
B12: 23 | H12: =SUM(D12:G12) -> 0 | I12: =C12-H12 -> 0
B13: 24 | H13: =SUM(D13:G13) -> 0 | I13: =C13-H13 -> 0
B14: 25 | H14: =SUM(D14:G14) -> 0 | I14: =C14-H14 -> 0
B15: 26 | H15: =SUM(D15:G15) -> 0 | I15: =C15-H15 -> 0
B16: 27 | H16: =SUM(D16:G16) -> 0 | I16: =C16-H16 -> 0
B17: 28 | H17: =SUM(D17:G17) -> 0 | I17: =C17-H17 -> 0
... B19: 30 | H19: =SUM(D19:G19) -> 0 | I19: =C19-H19 -> 0
H20: =SUM(D20:G20) -> 0 | I20: =C20-H20 -> 0
B21: TOTAL | C21: =SUM(C5:C19) -> 0 | D21: =SUM(D5:D19) -> 0 | E21: =SUM(E5:E19) -> 0 | F21: =SUM(F5:F19) -> 0 | G21: =SUM(G5:G19) -> 0 | H21: =SUM(H5:H19) -> 0
I22: =SUM(I5:I21) -> 0 | J22: TOTAL SALES
D24: EXPENSES
A25: MONTH | C25: GROSS SALES | D25: SALARY | E25: WATER-SUBSIDY | F25: PURCHASED | G25: OTHERS | H25: TOTAL EXPENSES | I25: NET SALES
A26: OCTOBER | B26: 1 | H26: =SUM(D26:G26) -> 0 | I26: =C26-H26 -> 0
B27: 2 | H27: =SUM(D27:G27) -> 0 | I27: =C27-H27 -> 0
B28: 3 | H28: =SUM(D28:G28) -> 0 | I28: =C28-H28 -> 0
B29: 4 | H29: =SUM(D29:G29) -> 0 | I29: =C29-H29 -> 0
B30: 5 | H30: =SUM(D30:G30) -> 0 | I30: =C30-H30 -> 0
B31: 6 | H31: =SUM(D31:G31) -> 0 | I31: =C31-H31 -> 0
B32: 7 | H32: =SUM(D32:G32) -> 0 | I32: =C32-H32 -> 0
B33: 8 | H33: =SUM(D33:G33) -> 0 | I33: =C33-H33 -> 0
B34: 9 | H34: =SUM(D34:G34) -> 0 | I34: =C34-H34 -> 0
B35: 10 | H35: =SUM(D35:G35) -> 0 | I35: =C35-H35 -> 0
B36: 11 | H36: =SUM(D36:G36) -> 0 | I36: =C36-H36 -> 0
B37: 12 | H37: =SUM(D37:G37) -> 0 | I37: =C37-H37 -> 0
B38: 13 | H38: =SUM(D38:G38) -> 0 | I38: =C38-H38 -> 0
... B55: 30 | H55: =SUM(D55:G55) -> 0 | I55: =C55-H55 -> 0
B56: 31
B57: TOTAL | C57: =SUM(C26:C56) -> 0 | D57: =SUM(D26:D56) -> 0 | E57: =SUM(E26:E56) -> 0 | F57: =SUM(F26:F56) -> 0 | G57: =SUM(G26:G56) -> 0 | H57: =SUM(H26:H56) -> 0 | I57: =SUM(I26:I56) -> 0
A60: MONTH | C60: GROSS SALES | D60: SALARY | E60: WATER-SUBSIDY | F60: PURCHASED | G60: OTHERS | H60: TOTAL EXPENSES | I60: NET SALES
...

Sheet TEACHERS AND ADMIN -ACCOUNTS
B1: RANZO NHS FACULTY AND STAFF MONTHLY ACCOUNTS
C2: SEPTEMBER | D2: OCTOBER | E2: NOVEMBER | F2: DECEMBER | G2: JANUARY | H2: FEBRUARY | I2: MARCH | J2: APRIL | K2: TOTAL
A3: 1 | B3: ACUESA, IVY JOY | K3: =SUM(C3:J3) -> 0
A4: 2 | B4: AGADIA, ROSANNA | K4: =SUM(C4:J4) -> 0
A5: 3 | B5: ARBADO, LIGAYA | K5: =SUM(C5:J5) -> 0
A6: 4 | B6: ARBADO, LOVELY | K6: =SUM(C6:J6) -> 0
A7: 5 | B7: BAUTISTA,JOSE | K7: =SUM(C7:J7) -> 0
A8: 6 | B8: BAYAMBAN, WILNER | K8: =SUM(C8:J8) -> 0
A9: 7 | B9: BENDOL, EDAMAE | K9: =SUM(C9:J9) -> 0
A10: 8 | B10: BUSAYONG, HANNAH JOY | K10: =SUM(C10:J10) -> 0
A11: 9 | B11: BUSAYONG, LYN | K11: =SUM(C11:J11) -> 0
A12: 10 | B12: DELOS SANTOS, GLORIA | K12: =SUM(C12:J12) -> 0
A13: 11 | B13: ELUSFA, PHEBE | K13: =SUM(C13:J13) -> 0
A14: 12 | B14: FELECIO, RIZZA | K14: =SUM(C14:J14) -> 0
... A35: 33 | B35: SPECIAL ACCOUNT E | K35: =SUM(C35:J35) -> 0
B36: TOTAL | C36: =SUM(C3:C35) -> 0 | D36: =SUM(D3:D35) -> 0 | E36: =SUM(E3:E35) -> 0 | F36: =SUM(F3:F35) -> 0 | G36: =SUM(G3:G35) -> 0 | H36: =SUM(H3:H35) -> 0 | I36: =SUM(I3:I35) -> 0 | J36: =SUM(J3:J35) -> 0 | K36: =SUM(K3:K35) -> 0

Sheet SUMMARY RECORDS
B2: MONTHLY SALES AND COLLECTIBLES REPORT
C3: MONTHLY SALES | D3: COLLECTIBLES (FACULTY AND STAFF)
B4: SEPTEMBER | C4: ='DAILY SALES RECORD'!I22 -> 0 | D4: ='TEACHERS AND ADMIN -ACCOUNTS'!C36 -> 0
B5: OCTOBER | C5: ='DAILY SALES RECORD'!I57 -> 0 | D5: ='TEACHERS AND ADMIN -ACCOUNTS'!D36 -> 0
B6: NOVEMBER | C6: ='DAILY SALES RECORD'!I91 -> 0 | D6: ='TEACHERS AND ADMIN -ACCOUNTS'!E36 -> 0
B7: DECEMBER | C7: ='DAILY SALES RECORD'!I124 -> 0 | D7: ='TEACHERS AND ADMIN -ACCOUNTS'!F36 -> 0
B8: JANUARY | C8: ='DAILY SALES RECORD'!I159 -> 0 | D8: ='TEACHERS AND ADMIN -ACCOUNTS'!G36 -> 0
B9: FEBRUARY | C9: ='DAILY SALES RECORD'!I192 -> 0 | D9: ='TEACHERS AND ADMIN -ACCOUNTS'!H36 -> 0
B10: MARCH | C10: ='DAILY SALES RECORD'!I226 -> 0 | D10: ='TEACHERS AND ADMIN -ACCOUNTS'!I36 -> 0
B11: APRIL | C11: ='DAILY SALES RECORD'!I259 -> 0 | D11: ='TEACHERS AND ADMIN -ACCOUNTS'!J36 -> 0
B12: TOTAL SALES | C12: =SUM(C4:C11) -> 0 | D12: =SUM(D4:D11) -> 0 | E12: =SUM(C12:D12) -> 0 | F12: EXPECTED WHOLE YEAR INCOME

Sheet DIVIDEND
A2: DIVIDENDS FOR 27 OFFICIAL MEMBERS
C3: PARTIAL-BASED TOTAL ANNUAL SALES (COH) | D3: PARTIAL-BASED TOTAL COLLECTIBLES | E3: COMBINED ANUAL DIVIDEND
C4: ='SUMMARY RECORDS'!C12/27 -> 0 | D4: ='SUMMARY RECORDS'!D12/27 -> 0 | E4: =C4+D4 -> 0
